Workbook

Sheet Toelichting
B1: Activiteitenbegroting invullen
B4: Waarom moet je laten zien dat subsidie nodig is?
B5: Volgens de Algemene Subsidieverordening (ASV) van de gemeente Breda is subsidie bedoeld voor activiteiten die zonder deze bijdrage niet kunnen doorgaan. Met deze begroting laat je zien welke activiteiten je organiseert, wat deze kosten, welke inkomsten je hebt en hoeveel subsidie je nodig hebt. En onderbouw je dat de subsidie nodig is om jouw activiteiten uit te voeren.
B9: Waarom is een sluitende begroting belangrijk?
B10: Een sluitende begroting laat zien dat je inkomsten en uitgaven met elkaar in balans zijn. Dit betekent dat alle kosten zijn betaald uit eigen inkomsten, bijdragen van anderen en de aangevraagde subsidie. Zo wordt duidelijk dat de begroting compleet en realistisch is en dat het aangevraagde subsidiebedrag goed is onderbouwd.
B14: Belangrijk: vul alleen de witte velden in. De pictogrammen en kleuren staan bovenaan de tabbladen waar je invult en controleert. Verwijder geen rijen, kolommen of formules. Dan blijven de automatische berekeningen goed werken.
B17: Bestand openen en bewerken
B18: Op een telefoon of tablet kun je dit bestand niet bewerken. Gebruik een computer.Krijg je de melding dat je het bestand alleen kunt lezen? Volg dan deze stappen: 1. Kies Bestand > Opslaan als > Een kopie downloaden. 2. Open rechtsboven de downloads via het pijltje naar beneden. Zie je het pijltje niet? Druk tegelijk op Ctrl en J om je downloads te openen. 3. Kies bij het gedownloade bestand voor Bestand openen. Je kunt het bestand nu bewerken.
B24: Zo vul je het bestand in
B25: 1 🟦 | C25: Start in tabblad: Begroting per activiteit
C26: Vul eerst je activiteiten in: korte omschrijving, hoe vaak je de activiteit organiseert en hoeveel mensen je bereikt.
B27: ↓
B29: 2 💶 | C29: Vul kosten in hetzelfde tabblad
C30: Vul de kosten in: medewerkers, inhuur, huisvesting, organisatiekosten en activiteitenkosten. Gebruik de grijze info-iconen voor uitleg.
B31: ↓
B33: 3 🟨 | C33: Bekijk het automatische overzicht kosten
C34: Dit overzicht staat onder de kosten. Je hoeft dit niet zelf in te vullen. Controleer alleen of de bedragen kloppen.
B35: ↓
B37: 4 ⬜ | C37: Vul inkomsten in hetzelfde tabblad
C38: Vul de inkomsten in: subsidie van gemeente Breda, sponsoring of giften, bijdragen van deelnemers, eigen bijdragen, andere subsidies en overige inkomsten.
B39: ↓
B41: 5 ✅ | C41: Ga naar tabblad: Totaaloverzicht en controle
C42: Doe hier de eindcontrole. Is de uitkomst 0? Dan is je begroting compleet. Is de uitkomst geen 0? Controleer dan je bedragen.
B44: Kort voorbeeld van een complete begroting
B45: Activiteit | C45: Kosten | D45: Inkomsten | E45: Controle
B46: Training | C46: 2500 | D46: 2500 | E46: 0 = compleet

Sheet Begroting per activiteit
B1: ACTIVITEITENBEGROTING SUBSIDIEAANVRAAG
C2: Geel vak = automatisch berekend. Niet invullen.
C3: Wit vak = zelf invullen. Laat de velden die niet van toepassing zijn leeg.
B4: i | C4: Grijs info-icoon = uitleg
B6: Naam organisatie | C6: Stichting Wielerevenementen Aalburg (handelsnaam Velo Vital)
B7: Naam project | C7: Velo Vital Breda - startronde leenfiets en fietsgroep voor vrouwen
B9: Activiteiten | C9: Activiteit 1 | D9: Activiteit 2 | E9: Activiteit 3 | F9: Activiteit 4 | G9: Activiteit 5 | H9: Activiteit 6 | I9: Activiteit 7 | J9: Activiteit 8
B10: Omschrijving Activiteiten | C10: Werving, campagne en intake van deelnemers | D10: Leenfietsen beschikbaar stellen, afstellen en onderhouden | E10: Begeleide fietsgroep: kennismakingsritten en vaste fietsmomenten | F10: Doorstroom naar zelfstandig fietsen, monitoring en eindrapportage
B11: Hoe vaak organiseer je deze activiteit? | C11: eenmalige wervingsronde, okt-dec 2026 | D11: doorlopend, dec 2026 - jun 2027 | E11: circa 20 ritten, jan-jun 2027 | F11: afrondende ronde, jun 2027
B12: Hoeveel mensen bereik je met deze activiteit? | C12: 10 | D12: 10 | E12: 10 | F12: 10
A14: ? | B14: Personeelskosten | C14: Activiteit 1 | D14: Activiteit 2 | E14: Activiteit 3 | F14: Activiteit 4 | G14: Activiteit 5 | H14: Activiteit 6 | I14: Activiteit 7 | J14: Activiteit 8 | K14: Totaal aanvraag
A15: ? | B15: Aantal medewerkers (fulltime omgerekend) | K15: =C15+D15+E15+F15+G15+H15+I15+J15 -> 0
A16: ? | B16: Gemiddeld salaris per fulltime medewerker | K16: =IFERROR(((C15*C16)+(D15*D16)+(E15*E16)+(F15*F16)+(G15*G16)+(H15*H16)+(I15*I16)+(J15*J16))/K15,0) -> 0
A17: ? | B17: Gemiddelde kosten voor management en ondersteuning | K17: =IFERROR(((C15*C17)+(D15*D17)+(E15*E17)+(F15*F17)+(G15*G17)+(H15*H17)+(I15*I17)+(J15*J17))/K15,0) -> 0
B18: Totaal | C18: =C15*(C16+C17) -> 0 | D18: =D15*(D16+D17) -> 0 | E18: =E15*(E16+E17) -> 0 | F18: =F15*(F16+F17) -> 0 | G18: =G15*(G16+G17) -> 0 | H18: =H15*(H16+H17) -> 0 | I18: =I15*(I16+I17) -> 0 | J18: =J15*(J16+J17) -> 0 | K18: =C18+D18+E18+F18+G18+H18+I18+J18 -> 0
A20: ? | B20: Personeelskosten inhuur | C20: Activiteit 1 | D20: Activiteit 2 | E20: Activiteit 3 | F20: Activiteit 4 | G20: Activiteit 5 | H20: Activiteit 6 | I20: Activiteit 7 | J20: Activiteit 8 | K20: Totaal aanvraag
A21: ? | B21: Aantal uren | K21: =C21+D21+E21+F21+G21+H21+I21+J21 -> 0
A22: ? | B22: Gemiddeld uurtarief inhuur | K22: =IFERROR(((C21*C22)+(D21*D22)+(E21*E22)+(F21*F22)+(G21*G22)+(H21*H22)+(I21*I22)+(J21*J22))/K21,0) -> 0
B23: Totaal | C23: =C21*C22 -> 0 | D23: =D21*D22 -> 0 | E23: =E21*E22 -> 0 | F23: =F21*F22 -> 0 | G23: =G21*G22 -> 0 | H23: =H21*H22 -> 0 | I23: =I21*I22 -> 0 | J23: =J21*J22 -> 0 | K23: =C23+D23+E23+F23+G23+H23+I23+J23 -> 0
A25: ? | B25: Huisvestingskosten | C25: Activiteit 1 | D25: Activiteit 2 | E25: Activiteit 3 | F25: Activiteit 4 | G25: Activiteit 5 | H25: Activiteit 6 | I25: Activiteit 7 | J25: Activiteit 8 | K25: Totaal aanvraag
K26: =C26+D26+E26+F26+G26+H26+I26+J26 -> 0
K27: =C27+D27+E27+F27+G27+H27+I27+J27 -> 0
K28: =C28+D28+E28+F28+G28+H28+I28+J28 -> 0
K29: =C29+D29+E29+F29+G29+H29+I29+J29 -> 0
K30: =C30+D30+E30+F30+G30+H30+I30+J30 -> 0
K31: 0
K32: 0
K33: 0
K34: 0
K35: 0
B36: Totaal | C36: =SUM(C26:C35) -> 0 | D36: =SUM(D26:D35) -> 0 | E36: =SUM(E26:E35) -> 0 | F36: =SUM(F26:F35) -> 0 | G36: =SUM(G26:G35) -> 0 | H36: =SUM(H26:H35) -> 0 | I36: =SUM(I26:I35) -> 0 | J36: =SUM(J26:J35) -> 0 | K36: =C36+D36+E36+F36+G36+H36+I36+J36 -> 0
A38: ? | B38: Organisatiekosten | C38: Activiteit 1 | D38: Activiteit 2 | E38: Activiteit 3 | F38: Activiteit 4 | G38: Activiteit 5 | H38: Activiteit 6 | I38: Activiteit 7 | J38: Activiteit 8 | K38: Totaal aanvraag
B39: Lokale campagne en werving in Breda | C39: 1400 | K39: =C39+D39+E39+F39+G39+H39+I39+J39 -> 1400
B40: Content en deelnemersverhalen voor werving | C40: 800 | K40: =C40+D40+E40+F40+G40+H40+I40+J40 -> 800
B41: Intake, aanmeldproces en deelnemersondersteuning | C41: 300 | K41: =C41+D41+E41+F41+G41+H41+I41+J41 -> 300
B42: Monitoring en eindrapportage | F42: 150 | K42: =C42+D42+E42+F42+G42+H42+I42+J42 -> 150
B43: Eigen inzet Velo Vital: organisatie en cooerdinatie (bijdrage in natura) | C43: 600 | D43: 600 | E43: 600 | F43: 200 | K43: =C43+D43+E43+F43+G43+H43+I43+J43 -> 2000
B44: Zichtbaarheid en bereik via lokale partners (bijdrage in natura) | C44: 1000 | K44: =C44+D44+E44+F44+G44+H44+I44+J44 -> 1000
K45: =C45+D45+E45+F45+G45+H45+I45+J45 -> 0
K46: =C46+D46+E46+F46+G46+H46+I46+J46 -> 0
...

Sheet Totaaloverzicht en controle
B1: Totaaloverzicht en controle
B3: 🟨 Geel = automatisch berekend ✅ Groen = controle klopt ⚠️ Rood = controleer de bedragen
B5: Naam organisatie | C5: ='Begroting per activiteit'!C6 -> Stichting Wielerevenementen Aalburg (handelsnaam Velo Vital)
B6: Naam project | C6: ='Begroting per activiteit'!C7 -> Velo Vital Breda - startronde leenfiets en fietsgroep voor vrouwen
B8: KOSTEN | C8: Activiteit 1 | D8: Activiteit 2 | E8: Activiteit 3 | F8: Activiteit 4 | G8: Activiteit 5 | H8: Activiteit 6 | I8: Activiteit 7 | J8: Activiteit 8 | K8: Totaal aanvraag
B9: Omschrijving Activiteiten | C9: ='Begroting per activiteit'!C10 -> Werving, campagne en intake van deelnemers | D9: ='Begroting per activiteit'!D10 -> Leenfietsen beschikbaar stellen, afstellen en onderhouden | E9: ='Begroting per activiteit'!E10 -> Begeleide fietsgroep: kennismakingsritten en vaste fietsmomenten | F9: ='Begroting per activiteit'!F10 -> Doorstroom naar zelfstandig fietsen, monitoring en eindrapportage | G9: ='Begroting per activiteit'!G10 -> 0 | H9: ='Begroting per activiteit'!H10 -> 0 | I9: ='Begroting per activiteit'!I10 -> 0 | J9: ='Begroting per activiteit'!J10 -> 0
B10: Personeelskosten | C10: ='Begroting per activiteit'!C70 -> 0 | D10: ='Begroting per activiteit'!D70 -> 0 | E10: ='Begroting per activiteit'!E70 -> 0 | F10: ='Begroting per activiteit'!F70 -> 0 | G10: ='Begroting per activiteit'!G70 -> 0 | H10: ='Begroting per activiteit'!H70 -> 0 | I10: ='Begroting per activiteit'!I70 -> 0 | J10: ='Begroting per activiteit'!J70 -> 0 | K10: =C10+D10+E10+F10+G10+H10+I10+J10 -> 0
B11: Personeelskosten inhuur | C11: ='Begroting per activiteit'!C71 -> 0 | D11: ='Begroting per activiteit'!D71 -> 0 | E11: ='Begroting per activiteit'!E71 -> 0 | F11: ='Begroting per activiteit'!F71 -> 0 | G11: ='Begroting per activiteit'!G71 -> 0 | H11: ='Begroting per activiteit'!H71 -> 0 | I11: ='Begroting per activiteit'!I71 -> 0 | J11: ='Begroting per activiteit'!J71 -> 0 | K11: =C11+D11+E11+F11+G11+H11+I11+J11 -> 0
B12: Huisvestingskosten | C12: ='Begroting per activiteit'!C72 -> 0 | D12: ='Begroting per activiteit'!D72 -> 0 | E12: ='Begroting per activiteit'!E72 -> 0 | F12: ='Begroting per activiteit'!F72 -> 0 | G12: ='Begroting per activiteit'!G72 -> 0 | H12: ='Begroting per activiteit'!H72 -> 0 | I12: ='Begroting per activiteit'!I72 -> 0 | J12: ='Begroting per activiteit'!J72 -> 0 | K12: =C12+D12+E12+F12+G12+H12+I12+J12 -> 0
B13: Organisatiekosten | C13: ='Begroting per activiteit'!C73 -> 4100 | D13: ='Begroting per activiteit'!D73 -> 600 | E13: ='Begroting per activiteit'!E73 -> 600 | F13: ='Begroting per activiteit'!F73 -> 350 | G13: ='Begroting per activiteit'!G73 -> 0 | H13: ='Begroting per activiteit'!H73 -> 0 | I13: ='Begroting per activiteit'!I73 -> 0 | J13: ='Begroting per activiteit'!J73 -> 0 | K13: =C13+D13+E13+F13+G13+H13+I13+J13 -> 5650
B14: Activiteitenkosten | C14: ='Begroting per activiteit'!C74 -> 0 | D14: ='Begroting per activiteit'!D74 -> 3600 | E14: ='Begroting per activiteit'!E74 -> 1750 | F14: ='Begroting per activiteit'!F74 -> 0 | G14: ='Begroting per activiteit'!G74 -> 0 | H14: ='Begroting per activiteit'!H74 -> 0 | I14: ='Begroting per activiteit'!I74 -> 0 | J14: ='Begroting per activiteit'!J74 -> 0 | K14: =C14+D14+E14+F14+G14+H14+I14+J14 -> 5350
B15: Totaal kosten | C15: =SUM(C10:C14) -> 4100 | D15: =SUM(D10:D14) -> 4200 | E15: =SUM(E10:E14) -> 2350 | F15: =SUM(F10:F14) -> 350 | G15: =SUM(G10:G14) -> 0 | H15: =SUM(H10:H14) -> 0 | I15: =SUM(I10:I14) -> 0 | J15: =SUM(J10:J14) -> 0 | K15: =SUM(K10:K14) -> 11000
B17: INKOMSTEN | C17: Activiteit 1 | D17: Activiteit 2 | E17: Activiteit 3 | F17: Activiteit 4 | G17: Activiteit 5 | H17: Activiteit 6 | I17: Activiteit 7 | J17: Activiteit 8 | K17: Totaal aanvraag
B18: Gevraagde subsidie gemeente Breda | C18: ='Begroting per activiteit'!C79 -> 2500 | D18: ='Begroting per activiteit'!D79 -> 1600 | E18: ='Begroting per activiteit'!E79 -> 750 | F18: ='Begroting per activiteit'!F79 -> 150 | G18: ='Begroting per activiteit'!G79 -> 0 | H18: ='Begroting per activiteit'!H79 -> 0 | I18: ='Begroting per activiteit'!I79 -> 0 | J18: ='Begroting per activiteit'!J79 -> 0 | K18: =C18+D18+E18+F18+G18+H18+I18+J18 -> 5000
B19: Sponsorbijdragen / Giften | C19: ='Begroting per activiteit'!C80 -> 0 | D19: ='Begroting per activiteit'!D80 -> 0 | E19: ='Begroting per activiteit'!E80 -> 0 | F19: ='Begroting per activiteit'!F80 -> 0 | G19: ='Begroting per activiteit'!G80 -> 0 | H19: ='Begroting per activiteit'!H80 -> 0 | I19: ='Begroting per activiteit'!I80 -> 0 | J19: ='Begroting per activiteit'!J80 -> 0 | K19: =C19+D19+E19+F19+G19+H19+I19+J19 -> 0
B20: Bijdragen deelnemers | C20: ='Begroting per activiteit'!C81 -> 0 | D20: ='Begroting per activiteit'!D81 -> 0 | E20: ='Begroting per activiteit'!E81 -> 0 | F20: ='Begroting per activiteit'!F81 -> 0 | G20: ='Begroting per activiteit'!G81 -> 0 | H20: ='Begroting per activiteit'!H81 -> 0 | I20: ='Begroting per activiteit'!I81 -> 0 | J20: ='Begroting per activiteit'!J81 -> 0 | K20: =C20+D20+E20+F20+G20+H20+I20+J20 -> 0
B21: Andere subsidies | C21: ='Begroting per activiteit'!C93 -> 0 | D21: ='Begroting per activiteit'!D93 -> 0 | E21: ='Begroting per activiteit'!E93 -> 0 | F21: ='Begroting per activiteit'!F93 -> 0 | G21: ='Begroting per activiteit'!G93 -> 0 | H21: ='Begroting per activiteit'!H93 -> 0 | I21: ='Begroting per activiteit'!I93 -> 0 | J21: ='Begroting per activiteit'!J93 -> 0 | K21: =C21+D21+E21+F21+G21+H21+I21+J21 -> 0
B22: Overige inkomsten | C22: ='Begroting per activiteit'!C102 -> 1600 | D22: ='Begroting per activiteit'!D102 -> 2600 | E22: ='Begroting per activiteit'!E102 -> 1600 | F22: ='Begroting per activiteit'!F102 -> 200 | G22: ='Begroting per activiteit'!G102 -> 0 | H22: ='Begroting per activiteit'!H102 -> 0 | I22: ='Begroting per activiteit'!I102 -> 0 | J22: ='Begroting per activiteit'!J102 -> 0 | K22: =C22+D22+E22+F22+G22+H22+I22+J22 -> 6000
B23: Totaal inkomsten | C23: =SUM(C18:C22) -> 4100 | D23: =SUM(D18:D22) -> 4200 | E23: =SUM(E18:E22) -> 2350 | F23: =SUM(F18:F22) -> 350 | G23: =SUM(G18:G22) -> 0 | H23: =SUM(H18:H22) -> 0 | I23: =SUM(I18:I22) -> 0 | J23: =SUM(J18:J22) -> 0 | K23: =C23+D23+E23+F23+G23+H23+I23+J23 -> 11000
B25: Controle begroting: 0 betekent dat kosten en inkomsten gelijk zijn | C25: =C15-C23 -> 0 | D25: =D15-D23 -> 0 | E25: =E15-E23 -> 0 | F25: =F15-F23 -> 0 | G25: =G15-G23 -> 0 | H25: =H15-H23 -> 0 | I25: =I15-I23 -> 0 | J25: =J15-J23 -> 0 | K25: =K15-K23 -> 0
B26: Let op: staat er iets anders dan 0? Controleer dan de kosten en inkomsten in het tabblad Begroting per activiteit.
B28: Samenvatting aangevraagde subsidie van gemeente Breda per activiteit
B29: Activiteit | C29: Omschrijving Activiteit | F29: Hoe vaak organiseer je deze activiteit? | G29: Hoeveel mensen bereik je? | H29: Aangevraagd subsidiebedrag
B30: Activiteit 1 | C30: ='Begroting per activiteit'!C10 -> Werving, campagne en intake van deelnemers | F30: ='Begroting per activiteit'!C11 -> eenmalige wervingsronde, okt-dec 2026 | G30: ='Begroting per activiteit'!C12 -> 10 | H30: =C18 -> 2500
B31: Activiteit 2 | C31: ='Begroting per activiteit'!D10 -> Leenfietsen beschikbaar stellen, afstellen en onderhouden | F31: ='Begroting per activiteit'!D11 -> doorlopend, dec 2026 - jun 2027 | G31: ='Begroting per activiteit'!D12 -> 10 | H31: =D18 -> 1600
B32: Activiteit 3 | C32: ='Begroting per activiteit'!E10 -> Begeleide fietsgroep: kennismakingsritten en vaste fietsmomenten | F32: ='Begroting per activiteit'!E11 -> circa 20 ritten, jan-jun 2027 | G32: ='Begroting per activiteit'!E12 -> 10 | H32: =E18 -> 750
B33: Activiteit 4 | C33: ='Begroting per activiteit'!F10 -> Doorstroom naar zelfstandig fietsen, monitoring en eindrapportage | F33: ='Begroting per activiteit'!F11 -> afrondende ronde, jun 2027 | G33: ='Begroting per activiteit'!F12 -> 10 | H33: =F18 -> 150
B34: Activiteit 5 | C34: ='Begroting per activiteit'!G10 -> 0 | F34: ='Begroting per activiteit'!G11 -> 0 | G34: ='Begroting per activiteit'!G12 -> 0 | H34: =G18 -> 0
B35: Activiteit 6 | C35: ='Begroting per activiteit'!H10 -> 0 | F35: ='Begroting per activiteit'!H11 -> 0 | G35: ='Begroting per activiteit'!H12 -> 0 | H35: =H18 -> 0
B36: Activiteit 7 | C36: ='Begroting per activiteit'!I10 -> 0 | F36: ='Begroting per activiteit'!I11 -> 0 | G36: ='Begroting per activiteit'!I12 -> 0 | H36: =I18 -> 0
B37: Activiteit 8 | C37: ='Begroting per activiteit'!J10 -> 0 | F37: ='Begroting per activiteit'!J11 -> 0 | G37: ='Begroting per activiteit'!J12 -> 0 | H37: =J18 -> 0
C38: Totaal | H38: =SUM(H30:H37) -> 5000
